Workbook

Sheet Dashboard
A1: Luma Vale | Excel dashboard
A2: Instant workbook view: yellow Catalogue and promotion edits flow through blue calculated Orders values.
A4: About this workbook
A5: Built first for a Shopify e-commerce store, then adapted as a credential-free public demo.
A6: This tab updates immediately in Excel. The polished interactive dashboard is published online.
A7: Online dashboard | B7: https://marginmap.eilvi.com/
A9: Live commercial picture | B9: Value | D9: After variable costs | E9: Value
A10: Gross sales | B10: =SUMPRODUCT(('Orders'!$E$3:$E$1200*'Orders'!$G$3:$G$1200)-'Orders'!$H$3:$H$1200) -> 83755.43 | D10: Contribution margin | E10: =B11 -> 51319.39
A11: Contribution margin | B11: =SUM(E27:E33) -> 51319.39 | D11: + Shipping charged ex VAT | E11: =ROUND(ROUND('Settings'!B13/(1+'Settings'!B6/100),2)*SUM('Orders'!$N$3:$N$1200),2) -> 2174.04
A12: Order lines | B12: =COUNTA('Orders'!$A$3:$A$1200) -> 1198 | D12: - Fulfilment | E12: =ROUND('Settings'!B12*SUM('Orders'!$N$3:$N$1200),2) -> 4811.4
A13: Units sold | B13: =SUM('Orders'!$G$3:$G$1200) -> 1358 | D13: - Payment fees | E13: =SUM('Orders'!$O$3:$O$1200) -> 1518.12
D14: - Advertising | E14: =SUM('Settings'!$B$19:$B$60) -> 11997
A15: Gross-sales benchmark | B15: Value | D15: After variable costs | E15: =E10+E11-E12-E13-E14 -> 35166.91
A16: Gross sales target | B16: ='Settings'!B8 -> 100000 | D16: Share of net sales | E16: =IF(SUM('Orders'!$I$3:$I$1200)=0,0,E15/SUM('Orders'!$I$3:$I$1200)) -> 0.5081
A17: Progress | B17: =B10/B16 -> 0.8376 | D17: Costs come from Settings. Not net profit.
A18: Remaining | B18: =MAX(B16-B10,0) -> 16244.57
A20: Data-driven observations
A21: =INDEX(B27:B33,MATCH(MAX(C27:C33),C27:C33,0))&" leads scenario gross sales at "&TEXT(MAX(C27:C33),"€#,##0")&"." -> Renewal Serum leads scenario gross sales at €26,205.
A22: =IF(COUNTIF('Pricing planner'!G6:G9,"Below cost")+COUNTIF('Pricing planner'!I13:I15,"Below cost")>0,"Price warning: at least one current offer is below cost. Review Pricing planner.","All current product and bundle prices are above cost.") -> All current product and bundle prices are above cost.
A23: =IF(B17>=1,"Gross-sales benchmark reached.",TEXT(B18,"€#,##0")&" remains to reach the benchmark.") -> €16,245 remains to reach the benchmark.
A25: Sales by SKU
A26: SKU | B26: Product | C26: Scenario gross sales | D26: Units | E26: Contribution margin | F26: Margin %
A27: ='Catalogue'!B3 -> SKU-A | B27: ='Catalogue'!C3 -> Renewal Serum | C27: =SUMPRODUCT(('Orders'!$C$3:$C$1200=A27)*(('Orders'!$E$3:$E$1200*'Orders'!$G$3:$G$1200)-'Orders'!$H$3:$H$1200)) -> 26205.28 | D27: =SUMIF('Orders'!$C$3:$C$1200,A27,'Orders'!$G$3:$G$1200) -> 395 | E27: =ROUND(SUMIF('Orders'!$C$3:$C$1200,A27,'Orders'!$I$3:$I$1200)-('Catalogue'!D3)*D27,2) -> 16601.39 | F27: =IF(C27=0,0,E27/SUMIF('Orders'!$C$3:$C$1200,A27,'Orders'!$I$3:$I$1200)) -> 0.766551
A28: ='Catalogue'!B4 -> SKU-B | B28: ='Catalogue'!C4 -> Barrier Balm | C28: =SUMPRODUCT(('Orders'!$C$3:$C$1200=A28)*(('Orders'!$E$3:$E$1200*'Orders'!$G$3:$G$1200)-'Orders'!$H$3:$H$1200)) -> 2713.2 | D28: =SUMIF('Orders'!$C$3:$C$1200,A28,'Orders'!$G$3:$G$1200) -> 150 | E28: =ROUND(SUMIF('Orders'!$C$3:$C$1200,A28,'Orders'!$I$3:$I$1200)-('Catalogue'!D4)*D28,2) -> 1657.02 | F28: =IF(C28=0,0,E28/SUMIF('Orders'!$C$3:$C$1200,A28,'Orders'!$I$3:$I$1200)) -> 0.738978
A29: ='Catalogue'!B5 -> SKU-C | B29: ='Catalogue'!C5 -> Contour Stone | C29: =SUMPRODUCT(('Orders'!$C$3:$C$1200=A29)*(('Orders'!$E$3:$E$1200*'Orders'!$G$3:$G$1200)-'Orders'!$H$3:$H$1200)) -> 2009.7 | D29: =SUMIF('Orders'!$C$3:$C$1200,A29,'Orders'!$G$3:$G$1200) -> 73 | E29: =ROUND(SUMIF('Orders'!$C$3:$C$1200,A29,'Orders'!$I$3:$I$1200)-('Catalogue'!D5)*D29,2) -> 1266.75 | F29: =IF(C29=0,0,E29/SUMIF('Orders'!$C$3:$C$1200,A29,'Orders'!$I$3:$I$1200)) -> 0.762685
A30: ='Catalogue'!B6 -> SKU-F | B30: ='Catalogue'!C6 -> Cloud Cleanser | C30: =SUMPRODUCT(('Orders'!$C$3:$C$1200=A30)*(('Orders'!$E$3:$E$1200*'Orders'!$G$3:$G$1200)-'Orders'!$H$3:$H$1200)) -> 2323.9 | D30: =SUMIF('Orders'!$C$3:$C$1200,A30,'Orders'!$G$3:$G$1200) -> 72 | E30: =ROUND(SUMIF('Orders'!$C$3:$C$1200,A30,'Orders'!$I$3:$I$1200)-('Catalogue'!D6)*D30,2) -> 1438.2 | F30: =IF(C30=0,0,E30/SUMIF('Orders'!$C$3:$C$1200,A30,'Orders'!$I$3:$I$1200)) -> 0.748837
A31: ='Catalogue'!B7 -> SKU-D | B31: ='Catalogue'!C7 -> Daily Duo | C31: =SUMPRODUCT(('Orders'!$C$3:$C$1200=A31)*(('Orders'!$E$3:$E$1200*'Orders'!$G$3:$G$1200)-'Orders'!$H$3:$H$1200)) -> 19599.9 | D31: =SUMIF('Orders'!$C$3:$C$1200,A31,'Orders'!$G$3:$G$1200) -> 262 | E31: =ROUND(SUMIF('Orders'!$C$3:$C$1200,A31,'Orders'!$I$3:$I$1200)-('Catalogue'!D3+'Catalogue'!D4)*D31,2) -> 11823.07 | F31: =IF(C31=0,0,E31/SUMIF('Orders'!$C$3:$C$1200,A31,'Orders'!$I$3:$I$1200)) -> 0.729897
A32: ='Catalogue'!B8 -> SKU-E | B32: ='Catalogue'!C8 -> Complete Ritual | C32: =SUMPRODUCT(('Orders'!$C$3:$C$1200=A32)*(('Orders'!$E$3:$E$1200*'Orders'!$G$3:$G$1200)-'Orders'!$H$3:$H$1200)) -> 19597.8 | D32: =SUMIF('Orders'!$C$3:$C$1200,A32,'Orders'!$G$3:$G$1200) -> 232 | E32: =ROUND(SUMIF('Orders'!$C$3:$C$1200,A32,'Orders'!$I$3:$I$1200)-('Catalogue'!D3+'Catalogue'!D5)*D32,2) -> 11973.88 | F32: =IF(C32=0,0,E32/SUMIF('Orders'!$C$3:$C$1200,A32,'Orders'!$I$3:$I$1200)) -> 0.739287
A33: ='Catalogue'!B9 -> SKU-G | B33: ='Catalogue'!C9 -> Daily Reset Set | C33: =SUMPRODUCT(('Orders'!$C$3:$C$1200=A33)*(('Orders'!$E$3:$E$1200*'Orders'!$G$3:$G$1200)-'Orders'!$H$3:$H$1200)) -> 11305.65 | D33: =SUMIF('Orders'!$C$3:$C$1200,A33,'Orders'!$G$3:$G$1200) -> 174 | E33: =ROUND(SUMIF('Orders'!$C$3:$C$1200,A33,'Orders'!$I$3:$I$1200)-('Catalogue'!D4+'Catalogue'!D5+'Catalogue'!D6)*D33,2) -> 6559.08 | F33: =IF(C33=0,0,E33/SUMIF('Orders'!$C$3:$C$1200,A33,'Orders'!$I$3:$I$1200)) -> 0.701993
A35: Target chart data | B35: Value
A36: Achieved | B36: =MIN(B10,B16) -> 83755.43
A37: Remaining | B37: =MAX(B16-B10,0) -> 16244.57

Sheet Read me
A1: Luma Vale | editable unit economics input
A2: Start with Dashboard. Edit yellow cells only; blue and purple cells calculate automatically.
A4: Sheet | B4: What it is for
A5: Dashboard | B5: Live, formula-driven Excel companion, including what remains after variable costs. The polished interactive dashboard is online.
A6: Settings | B6: Store identity, VAT rate, targets, pricing mode and optional fulfilment, payment and advertising costs.
A7: Catalogue | B7: Products and bundles together. Use Type to distinguish them.
A8: Pricing & promotions | B8: Price history and the discount rules that drive calculated order discounts.
A9: Pricing planner | B9: Live Excel price, margin and bundle-saving checks. It updates when yellow price inputs change.
A10: Orders | B10: Blue price and discount cells follow Catalogue and promotion inputs in Scenario mode.
A12: This copy holds 1198 order lines across 891 orders (1358 units, EUR 83,755 gross after discounts) for the 12 months to 2026-10-22.
A13: Regenerate it any time with: python3 src/make_demo_workbook.py

Sheet Settings
A1: Settings
A2: Setting | B2: Value
A3: Store name | B3: Luma Vale
A4: Store domain | B4: lumavale.example
A5: Currency | B5: EUR
A6: VAT rate (%) | B6: 21
A7: Target units | B7: 1500
A8: Gross sales target | B8: 100000
A9: Target start | B9: 2026-01-01
A10: Target end | B10: 2026-12-31
A11: Pricing model | B11: Scenario
A12: Fulfilment cost per order ex VAT | B12: 5.4
A13: Shipping charged per order incl VAT | B13: 2.95
A14: Payment fee (%) | B14: 1.5
A15: Payment fee per order | B15: 0.25
A17: Advertising by month | optional
A18: Month (YYYY-MM) | B18: Advertising spend ex VAT
A19: 2025-10 | B19: 1035
A20: 2025-11 | B20: 1305
A21: 2025-12 | B21: 1170
A22: 2026-01 | B22: 702
A23: 2026-02 | B23: 765
A24: 2026-03 | B24: 855
A25: 2026-04 | B25: 900
A26: 2026-05 | B26: 945
A27: 2026-06 | B27: 855
A28: 2026-07 | B28: 792
A29: 2026-08 | B29: 720
A30: 2026-09 | B30: 918
A31: 2026-10 | B31: 1035
A33: Leave the four cost rows and this table blank to see product margin only. Per-order costs are shared across lines by value; advertising by each month's net revenue.

Sheet Catalogue
A1: Catalogue
A2: Type | B2: SKU | C2: Name | D2: Unit cost ex VAT | E2: Web price incl VAT | F2: Batch quantity | G2: Stock on hand | H2: Bundle contents | I2: Declared solo total | J2: Claimed saving | K2: Confirmed (TRUE/FALSE) | L2: Cost source | M2: Notes | N2: Bundle discount %
A3: Product | B3: SKU-A | C3: Renewal Serum | D3: 12.8 | E3: 69.9 | F3: 4000 | G3: 1180 | L3: Synthetic supplier invoice | M3: Hero product
A4: Product | B4: SKU-B | C4: Barrier Balm | D4: 3.9 | E4: 19 | F4: 2200 | G4: 940 | L4: Synthetic supplier invoice | M4: Add-on product
A5: Product | B5: SKU-C | C5: Contour Stone | D5: 5.4 | E5: 29 | F5: 1200 | G5: 145 | L5: Synthetic supplier invoice | M5: Accessory, tightest stock line
A6: Product | B6: SKU-F | C6: Cloud Cleanser | D6: 6.7 | E6: 34 | F6: 1800 | G6: 690 | L6: Synthetic supplier invoice | M6: Daily-use cleanser
A7: Bundle | B7: SKU-D | C7: Daily Duo | E7: =ROUND(I7*(1-N7),2) -> 79 | H7: SKU-A:1|SKU-B:1 | I7: =E3+E4 -> 88.9 | J7: =ROUND(I7-E7,2) -> 9.9 | K7: TRUE | M7: Core bundle | N7: 0.111361
A8: Bundle | B8: SKU-E | C8: Complete Ritual | E8: =ROUND(I8*(1-N8),2) -> 89 | H8: SKU-A:1|SKU-C:1 | I8: =E3+E5 -> 98.9 | J8: =ROUND(I8-E8,2) -> 9.9 | K8: TRUE | M8: Premium bundle | N8: 0.100101
A9: Bundle | B9: SKU-G | C9: Daily Reset Set | E9: =ROUND(I9*(1-N9),2) -> 69 | H9: SKU-B:1|SKU-C:1|SKU-F:1 | I9: =E4+E5+E6 -> 82 | J9: =ROUND(I9-E9,2) -> 13 | K9: TRUE | M9: Three-product starter bundle | N9: 0.158537

Sheet Pricing & promotions
A1: Pricing & promotions
A2: Edit yellow promotion rules. Scenario-mode Orders discounts recalculate from these values.
A4: Promotion rules | live scenario inputs
A5: Discount code | B5: Discount % | C5: Active from | D5: Active to | E5: Status
A6: WELCOME10 | B6: 10 | C6: 2025-08-01 | D6: 2026-12-31 | E6: TRUE
A7: SUMMER15 | B7: 15 | C7: 2025-08-01 | D7: 2026-12-31 | E7: TRUE
A8: VIP20 | B8: 20 | C8: 2025-08-01 | D8: 2026-12-31 | E8: TRUE
A10: Price history | reference for Actual mode
A11: SKU | B11: Start date | C11: Price incl VAT | D11: Source
A12: SKU-A | B12: 2025-08-01 | C12: 64 | D12: Synthetic launch price
A13: SKU-A | B13: 2026-01-01 | C13: 69.9 | D13: Synthetic price increase
A14: SKU-B | B14: 2025-08-01 | C14: 18 | D14: Synthetic launch price
A15: SKU-B | B15: 2026-03-01 | C15: 19 | D15: Synthetic price increase
A16: SKU-C | B16: 2025-08-01 | C16: 29 | D16: Synthetic launch price
A17: SKU-F | B17: 2025-08-01 | C17: 34 | D17: Synthetic launch price

Sheet Pricing planner
A1: Pricing planner | live Excel checks
A2: Change only yellow cells in Catalogue. This sheet updates immediately in Excel, Numbers or LibreOffice.
A4: Product price health
A5: SKU | B5: Product | C5: Unit cost ex VAT | D5: Web price incl VAT | E5: Gross profit ex VAT | F5: Gross margin % | G5: Status
A6: ='Catalogue'!B3 -> SKU-A | B6: ='Catalogue'!C3 -> Renewal Serum | C6: ='Catalogue'!D3 -> 12.8 | D6: ='Catalogue'!E3 -> 69.9 | E6: =ROUND(D6/(1+'Settings'!B6/100)-C6,2) -> 44.97 | F6: =IF(D6<=0,0,E6/(D6/(1+'Settings'!B6/100)) ) -> 0.7784 | G6: =IF(D6<=0,"FIX: price must be positive",IF(E6<0,"Below cost",IF(F6<0.5,"Low margin","Healthy"))) -> Healthy
A7: ='Catalogue'!B4 -> SKU-B | B7: ='Catalogue'!C4 -> Barrier Balm | C7: ='Catalogue'!D4 -> 3.9 | D7: ='Catalogue'!E4 -> 19 | E7: =ROUND(D7/(1+'Settings'!B6/100)-C7,2) -> 11.8 | F7: =IF(D7<=0,0,E7/(D7/(1+'Settings'!B6/100)) ) -> 0.7516 | G7: =IF(D7<=0,"FIX: price must be positive",IF(E7<0,"Below cost",IF(F7<0.5,"Low margin","Healthy"))) -> Healthy
A8: ='Catalogue'!B5 -> SKU-C | B8: ='Catalogue'!C5 -> Contour Stone | C8: ='Catalogue'!D5 -> 5.4 | D8: ='Catalogue'!E5 -> 29 | E8: =ROUND(D8/(1+'Settings'!B6/100)-C8,2) -> 18.57 | F8: =IF(D8<=0,0,E8/(D8/(1+'Settings'!B6/100)) ) -> 0.7747 | G8: =IF(D8<=0,"FIX: price must be positive",IF(E8<0,"Below cost",IF(F8<0.5,"Low margin","Healthy"))) -> Healthy
A9: ='Catalogue'!B6 -> SKU-F | B9: ='Catalogue'!C6 -> Cloud Cleanser | C9: ='Catalogue'!D6 -> 6.7 | D9: ='Catalogue'!E6 -> 34 | E9: =ROUND(D9/(1+'Settings'!B6/100)-C9,2) -> 21.4 | F9: =IF(D9<=0,0,E9/(D9/(1+'Settings'!B6/100)) ) -> 0.7616 | G9: =IF(D9<=0,"FIX: price must be positive",IF(E9<0,"Below cost",IF(F9<0.5,"Low margin","Healthy"))) -> Healthy
A11: Bundle price health
A12: SKU | B12: Bundle | C12: Bundle price incl VAT | D12: Buy separately | E12: Customer saving | F12: Discount % | G12: Product cost ex VAT | H12: Contribution ex VAT | I12: Status
A13: ='Catalogue'!B7 -> SKU-D | B13: ='Catalogue'!C7 -> Daily Duo | C13: ='Catalogue'!E7 -> 79 | D13: ='Catalogue'!I7 -> 88.9 | E13: ='Catalogue'!J7 -> 9.9 | F13: ='Catalogue'!N7 -> 0.1114 | G13: ='Catalogue'!D3+'Catalogue'!D4 -> 16.7 | H13: =ROUND(C13/(1+'Settings'!B6/100)-G13,2) -> 48.59 | I13: =IF(C13<=0,"FIX: price must be positive",IF(H13<0,"Below cost",IF(C13>=D13,"No customer saving","Healthy"))) -> Healthy
A14: ='Catalogue'!B8 -> SKU-E | B14: ='Catalogue'!C8 -> Complete Ritual | C14: ='Catalogue'!E8 -> 89 | D14: ='Catalogue'!I8 -> 98.9 | E14: ='Catalogue'!J8 -> 9.9 | F14: ='Catalogue'!N8 -> 0.1001 | G14: ='Catalogue'!D3+'Catalogue'!D5 -> 18.2 | H14: =ROUND(C14/(1+'Settings'!B6/100)-G14,2) -> 55.35 | I14: =IF(C14<=0,"FIX: price must be positive",IF(H14<0,"Below cost",IF(C14>=D14,"No customer saving","Healthy"))) -> Healthy
A15: ='Catalogue'!B9 -> SKU-G | B15: ='Catalogue'!C9 -> Daily Reset Set | C15: ='Catalogue'!E9 -> 69 | D15: ='Catalogue'!I9 -> 82 | E15: ='Catalogue'!J9 -> 13 | F15: ='Catalogue'!N9 -> 0.1585 | G15: ='Catalogue'!D4+'Catalogue'!D5+'Catalogue'!D6 -> 16 | H15: =ROUND(C15/(1+'Settings'!B6/100)-G15,2) -> 41.02 | I15: =IF(C15<=0,"FIX: price must be positive",IF(H15<0,"Below cost",IF(C15>=D15,"No customer saving","Healthy"))) -> Healthy

Sheet Orders
A1: Orders
A2: Order ID | B2: Order date | C2: SKU | D2: Product title | E2: Unit price incl VAT | F2: Recorded unit price incl VAT | G2: Quantity | H2: Discount allocated incl VAT | I2: Revenue ex VAT | J2: Recorded discount incl VAT | K2: Taxable (TRUE/FALSE) | L2: Discount code | M2: Gross line sales | N2: First line of order | O2: Payment fee per order
A3: #1001 | B3: 2025-10-22 | C3: SKU-D | D3: Daily Duo | E3: =IF('Settings'!$B$11="Scenario",IFERROR(INDEX('Catalogue'!$E$3:$E$100,MATCH(C3,'Catalogue'!$B$3:$B$100,0)),F3),F3) -> 79 | F3: 79 | G3: 1 | H3: =IF('Settings'!$B$11="Scenario",ROUND(E3*G3*IFERROR(SUMIF('Pricing & promotions'!$A$6:$A$8,L3,'Pricing & promotions'!$B$6:$B$8)/100,0),2),J3) -> 7.9 | I3: =ROUND((E3*G3-H3)/IF(OR(K3=TRUE,K3="TRUE",K3="YES",K3=1),1+'Settings'!$B$6/100,1),2) -> 58.76 | J3: 7.9 | K3: TRUE | L3: WELCOME10 | M3: =ROUND(E3*G3-H3,2) -> 71.1 | N3: =IF(COUNTIF($A$3:A3,A3)=1,1,0) -> 1 | O3: =IF(N3=1,ROUND((SUMIFS($M$3:$M$1200,$A$3:$A$1200,A3)+'Settings'!$B$13)*'Settings'!$B$14/100+'Settings'!$B$15,2),0) -> 2.56
A4: #1001 | B4: 2025-10-22 | C4: SKU-E | D4: Complete Ritual | E4: =IF('Settings'!$B$11="Scenario",IFERROR(INDEX('Catalogue'!$E$3:$E$100,MATCH(C4,'Catalogue'!$B$3:$B$100,0)),F4),F4) -> 89 | F4: 89 | G4: 1 | H4: =IF('Settings'!$B$11="Scenario",ROUND(E4*G4*IFERROR(SUMIF('Pricing & promotions'!$A$6:$A$8,L4,'Pricing & promotions'!$B$6:$B$8)/100,0),2),J4) -> 8.9 | I4: =ROUND((E4*G4-H4)/IF(OR(K4=TRUE,K4="TRUE",K4="YES",K4=1),1+'Settings'!$B$6/100,1),2) -> 66.2 | J4: 8.9 | K4: TRUE | L4: WELCOME10 | M4: =ROUND(E4*G4-H4,2) -> 80.1 | N4: =IF(COUNTIF($A$3:A4,A4)=1,1,0) -> 0 | O4: =IF(N4=1,ROUND((SUMIFS($M$3:$M$1200,$A$3:$A$1200,A4)+'Settings'!$B$13)*'Settings'!$B$14/100+'Settings'!$B$15,2),0) -> 0
A5: #1002 | B5: 2025-10-23 | C5: SKU-A | D5: Renewal Serum | E5: =IF('Settings'!$B$11="Scenario",IFERROR(INDEX('Catalogue'!$E$3:$E$100,MATCH(C5,'Catalogue'!$B$3:$B$100,0)),F5),F5) -> 69.9 | F5: 64 | G5: 1 | H5: =IF('Settings'!$B$11="Scenario",ROUND(E5*G5*IFERROR(SUMIF('Pricing & promotions'!$A$6:$A$8,L5,'Pricing & promotions'!$B$6:$B$8)/100,0),2),J5) -> 10.49 | I5: =ROUND((E5*G5-H5)/IF(OR(K5=TRUE,K5="TRUE",K5="YES",K5=1),1+'Settings'!$B$6/100,1),2) -> 49.1 | J5: 9.6 | K5: TRUE | L5: SUMMER15 | M5: =ROUND(E5*G5-H5,2) -> 59.41 | N5: =IF(COUNTIF($A$3:A5,A5)=1,1,0) -> 1 | O5: =IF(N5=1,ROUND((SUMIFS($M$3:$M$1200,$A$3:$A$1200,A5)+'Settings'!$B$13)*'Settings'!$B$14/100+'Settings'!$B$15,2),0) -> 1.19
A6: #1003 | B6: 2025-10-23 | C6: SKU-F | D6: Cloud Cleanser | E6: =IF('Settings'!$B$11="Scenario",IFERROR(INDEX('Catalogue'!$E$3:$E$100,MATCH(C6,'Catalogue'!$B$3:$B$100,0)),F6),F6) -> 34 | F6: 34 | G6: 1 | H6: =IF('Settings'!$B$11="Scenario",ROUND(E6*G6*IFERROR(SUMIF('Pricing & promotions'!$A$6:$A$8,L6,'Pricing & promotions'!$B$6:$B$8)/100,0),2),J6) -> 0 | I6: =ROUND((E6*G6-H6)/IF(OR(K6=TRUE,K6="TRUE",K6="YES",K6=1),1+'Settings'!$B$6/100,1),2) -> 28.1 | J6: 0 | K6: TRUE | M6: =ROUND(E6*G6-H6,2) -> 34 | N6: =IF(COUNTIF($A$3:A6,A6)=1,1,0) -> 1 | O6: =IF(N6=1,ROUND((SUMIFS($M$3:$M$1200,$A$3:$A$1200,A6)+'Settings'!$B$13)*'Settings'!$B$14/100+'Settings'!$B$15,2),0) -> 0.8
A7: #1004 | B7: 2025-10-23 | C7: SKU-A | D7: Renewal Serum | E7: =IF('Settings'!$B$11="Scenario",IFERROR(INDEX('Catalogue'!$E$3:$E$100,MATCH(C7,'Catalogue'!$B$3:$B$100,0)),F7),F7) -> 69.9 | F7: 64 | G7: 1 | H7: =IF('Settings'!$B$11="Scenario",ROUND(E7*G7*IFERROR(SUMIF('Pricing & promotions'!$A$6:$A$8,L7,'Pricing & promotions'!$B$6:$B$8)/100,0),2),J7) -> 6.99 | I7: =ROUND((E7*G7-H7)/IF(OR(K7=TRUE,K7="TRUE",K7="YES",K7=1),1+'Settings'!$B$6/100,1),2) -> 51.99 | J7: 6.4 | K7: TRUE | L7: WELCOME10 | M7: =ROUND(E7*G7-H7,2) -> 62.91 | N7: =IF(COUNTIF($A$3:A7,A7)=1,1,0) -> 1 | O7: =IF(N7=1,ROUND((SUMIFS($M$3:$M$1200,$A$3:$A$1200,A7)+'Settings'!$B$13)*'Settings'!$B$14/100+'Settings'!$B$15,2),0) -> 1.24
A8: #1005 | B8: 2025-10-24 | C8: SKU-D | D8: Daily Duo | E8: =IF('Settings'!$B$11="Scenario",IFERROR(INDEX('Catalogue'!$E$3:$E$100,MATCH(C8,'Catalogue'!$B$3:$B$100,0)),F8),F8) -> 79 | F8: 79 | G8: 1 | H8: =IF('Settings'!$B$11="Scenario",ROUND(E8*G8*IFERROR(SUMIF('Pricing & promotions'!$A$6:$A$8,L8,'Pricing & promotions'!$B$6:$B$8)/100,0),2),J8) -> 0 | I8: =ROUND((E8*G8-H8)/IF(OR(K8=TRUE,K8="TRUE",K8="YES",K8=1),1+'Settings'!$B$6/100,1),2) -> 65.29 | J8: 0 | K8: TRUE | M8: =ROUND(E8*G8-H8,2) -> 79 | N8: =IF(COUNTIF($A$3:A8,A8)=1,1,0) -> 1 | O8: =IF(N8=1,ROUND((SUMIFS($M$3:$M$1200,$A$3:$A$1200,A8)+'Settings'!$B$13)*'Settings'!$B$14/100+'Settings'!$B$15,2),0) -> 1.48
A9: #1006 | B9: 2025-10-24 | C9: SKU-E | D9: Complete Ritual | E9: =IF('Settings'!$B$11="Scenario",IFERROR(INDEX('Catalogue'!$E$3:$E$100,MATCH(C9,'Catalogue'!$B$3:$B$100,0)),F9),F9) -> 89 | F9: 89 | G9: 1 | H9: =IF('Settings'!$B$11="Scenario",ROUND(E9*G9*IFERROR(SUMIF('Pricing & promotions'!$A$6:$A$8,L9,'Pricing & promotions'!$B$6:$B$8)/100,0),2),J9) -> 0 | I9: =ROUND((E9*G9-H9)/IF(OR(K9=TRUE,K9="TRUE",K9="YES",K9=1),1+'Settings'!$B$6/100,1),2) -> 73.55 | J9: 0 | K9: TRUE | M9: =ROUND(E9*G9-H9,2) -> 89 | N9: =IF(COUNTIF($A$3:A9,A9)=1,1,0) -> 1 | O9: =IF(N9=1,ROUND((SUMIFS($M$3:$M$1200,$A$3:$A$1200,A9)+'Settings'!$B$13)*'Settings'!$B$14/100+'Settings'!$B$15,2),0) -> 1.63
A10: #1007 | B10: 2025-10-24 | C10: SKU-A | D10: Renewal Serum | E10: =IF('Settings'!$B$11="Scenario",IFERROR(INDEX('Catalogue'!$E$3:$E$100,MATCH(C10,'Catalogue'!$B$3:$B$100,0)),F10),F10) -> 69.9 | F10: 64 | G10: 2 | H10: =IF('Settings'!$B$11="Scenario",ROUND(E10*G10*IFERROR(SUMIF('Pricing & promotions'!$A$6:$A$8,L10,'Pricing & promotions'!$B$6:$B$8)/100,0),2),J10) -> 0 | I10: =ROUND((E10*G10-H10)/IF(OR(K10=TRUE,K10="TRUE",K10="YES",K10=1),1+'Settings'!$B$6/100,1),2) -> 115.54 | J10: 0 | K10: TRUE | M10: =ROUND(E10*G10-H10,2) -> 139.8 | N10: =IF(COUNTIF($A$3:A10,A10)=1,1,0) -> 1 | O10: =IF(N10=1,ROUND((SUMIFS($M$3:$M$1200,$A$3:$A$1200,A10)+'Settings'!$B$13)*'Settings'!$B$14/100+'Settings'!$B$15,2),0) -> 2.39
A11: #1008 | B11: 2025-10-25 | C11: SKU-D | D11: Daily Duo | E11: =IF('Settings'!$B$11="Scenario",IFERROR(INDEX('Catalogue'!$E$3:$E$100,MATCH(C11,'Catalogue'!$B$3:$B$100,0)),F11),F11) -> 79 | F11: 79 | G11: 1 | H11: =IF('Settings'!$B$11="Scenario",ROUND(E11*G11*IFERROR(SUMIF('Pricing & promotions'!$A$6:$A$8,L11,'Pricing & promotions'!$B$6:$B$8)/100,0),2),J11) -> 7.9 | I11: =ROUND((E11*G11-H11)/IF(OR(K11=TRUE,K11="TRUE",K11="YES",K11=1),1+'Settings'!$B$6/100,1),2) -> 58.76 | J11: 7.9 | K11: TRUE | L11: WELCOME10 | M11: =ROUND(E11*G11-H11,2) -> 71.1 | N11: =IF(COUNTIF($A$3:A11,A11)=1,1,0) -> 1 | O11: =IF(N11=1,ROUND((SUMIFS($M$3:$M$1200,$A$3:$A$1200,A11)+'Settings'!$B$13)*'Settings'!$B$14/100+'Settings'!$B$15,2),0) -> 2.3
A12: #1008 | B12: 2025-10-25 | C12: SKU-A | D12: Renewal Serum | E12: =IF('Settings'!$B$11="Scenario",IFERROR(INDEX('Catalogue'!$E$3:$E$100,MATCH(C12,'Catalogue'!$B$3:$B$100,0)),F12),F12) -> 69.9 | F12: 64 | G12: 1 | H12: =IF('Settings'!$B$11="Scenario",ROUND(E12*G12*IFERROR(SUMIF('Pricing & promotions'!$A$6:$A$8,L12,'Pricing & promotions'!$B$6:$B$8)/100,0),2),J12) -> 6.99 | I12: =ROUND((E12*G12-H12)/IF(OR(K12=TRUE,K12="TRUE",K12="YES",K12=1),1+'Settings'!$B$6/100,1),2) -> 51.99 | J12: 6.4 | K12: TRUE | L12: WELCOME10 | M12: =ROUND(E12*G12-H12,2) -> 62.91 | N12: =IF(COUNTIF($A$3:A12,A12)=1,1,0) -> 0 | O12: =IF(N12=1,ROUND((SUMIFS($M$3:$M$1200,$A$3:$A$1200,A12)+'Settings'!$B$13)*'Settings'!$B$14/100+'Settings'!$B$15,2),0) -> 0
A13: #1009 | B13: 2025-10-25 | C13: SKU-F | D13: Cloud Cleanser | E13: =IF('Settings'!$B$11="Scenario",IFERROR(INDEX('Catalogue'!$E$3:$E$100,MATCH(C13,'Catalogue'!$B$3:$B$100,0)),F13),F13) -> 34 | F13: 34 | G13: 2 | H13: =IF('Settings'!$B$11="Scenario",ROUND(E13*G13*IFERROR(SUMIF('Pricing & promotions'!$A$6:$A$8,L13,'Pricing & promotions'!$B$6:$B$8)/100,0),2),J13) -> 6.8 | I13: =ROUND((E13*G13-H13)/IF(OR(K13=TRUE,K13="TRUE",K13="YES",K13=1),1+'Settings'!$B$6/100,1),2) -> 50.58 | J13: 6.8 | K13: TRUE | L13: WELCOME10 | M13: =ROUND(E13*G13-H13,2) -> 61.2 | N13: =IF(COUNTIF($A$3:A13,A13)=1,1,0) -> 1 | O13: =IF(N13=1,ROUND((SUMIFS($M$3:$M$1200,$A$3:$A$1200,A13)+'Settings'!$B$13)*'Settings'!$B$14/100+'Settings'!$B$15,2),0) -> 1.47
A14: #1009 | B14: 2025-10-25 | C14: SKU-B | D14: Barrier Balm | E14: =IF('Settings'!$B$11="Scenario",IFERROR(INDEX('Catalogue'!$E$3:$E$100,MATCH(C14,'Catalogue'!$B$3:$B$100,0)),F14),F14) -> 19 | F14: 18 | G14: 1 | H14: =IF('Settings'!$B$11="Scenario",ROUND(E14*G14*IFERROR(SUMIF('Pricing & promotions'!$A$6:$A$8,L14,'Pricing & promotions'!$B$6:$B$8)/100,0),2),J14) -> 1.9 | I14: =ROUND((E14*G14-H14)/IF(OR(K14=TRUE,K14="TRUE",K14="YES",K14=1),1+'Settings'!$B$6/100,1),2) -> 14.13 | J14: 1.8 | K14: TRUE | L14: WELCOME10 | M14: =ROUND(E14*G14-H14,2) -> 17.1 | N14: =IF(COUNTIF($A$3:A14,A14)=1,1,0) -> 0 | O14: =IF(N14=1,ROUND((SUMIFS($M$3:$M$1200,$A$3:$A$1200,A14)+'Settings'!$B$13)*'Settings'!$B$14/100+'Settings'!$B$15,2),0) -> 0
A15: #1010 | B15: 2025-10-25 | C15: SKU-A | D15: Renewal Serum | E15: =IF('Settings'!$B$11="Scenario",IFERROR(INDEX('Catalogue'!$E$3:$E$100,MATCH(C15,'Catalogue'!$B$3:$B$100,0)),F15),F15) -> 69.9 | F15: 64 | G15: 1 | H15: =IF('Settings'!$B$11="Scenario",ROUND(E15*G15*IFERROR(SUMIF('Pricing & promotions'!$A$6:$A$8,L15,'Pricing & promotions'!$B$6:$B$8)/100,0),2),J15) -> 0 | I15: =ROUND((E15*G15-H15)/IF(OR(K15=TRUE,K15="TRUE",K15="YES",K15=1),1+'Settings'!$B$6/100,1),2) -> 57.77 | J15: 0 | K15: TRUE | M15: =ROUND(E15*G15-H15,2) -> 69.9 | N15: =IF(COUNTIF($A$3:A15,A15)=1,1,0) -> 1 | O15: =IF(N15=1,ROUND((SUMIFS($M$3:$M$1200,$A$3:$A$1200,A15)+'Settings'!$B$13)*'Settings'!$B$14/100+'Settings'!$B$15,2),0) -> 2.68
A16: #1010 | B16: 2025-10-25 | C16: SKU-E | D16: Complete Ritual | E16: =IF('Settings'!$B$11="Scenario",IFERROR(INDEX('Catalogue'!$E$3:$E$100,MATCH(C16,'Catalogue'!$B$3:$B$100,0)),F16),F16) -> 89 | F16: 89 | G16: 1 | H16: =IF('Settings'!$B$11="Scenario",ROUND(E16*G16*IFERROR(SUMIF('Pricing & promotions'!$A$6:$A$8,L16,'Pricing & promotions'!$B$6:$B$8)/100,0),2),J16) -> 0 | I16: =ROUND((E16*G16-H16)/IF(OR(K16=TRUE,K16="TRUE",K16="YES",K16=1),1+'Settings'!$B$6/100,1),2) -> 73.55 | J16: 0 | K16: TRUE | M16: =ROUND(E16*G16-H16,2) -> 89 | N16: =IF(COUNTIF($A$3:A16,A16)=1,1,0) -> 0 | O16: =IF(N16=1,ROUND((SUMIFS($M$3:$M$1200,$A$3:$A$1200,A16)+'Settings'!$B$13)*'Settings'!$B$14/100+'Settings'!$B$15,2),0) -> 0
A17: #1011 | B17: 2025-10-26 | C17: SKU-A | D17: Renewal Serum | E17: =IF('Settings'!$B$11="Scenario",IFERROR(INDEX('Catalogue'!$E$3:$E$100,MATCH(C17,'Catalogue'!$B$3:$B$100,0)),F17),F17) -> 69.9 | F17: 64 | G17: 1 | H17: =IF('Settings'!$B$11="Scenario",ROUND(E17*G17*IFERROR(SUMIF('Pricing & promotions'!$A$6:$A$8,L17,'Pricing & promotions'!$B$6:$B$8)/100,0),2),J17) -> 10.49 | I17: =ROUND((E17*G17-H17)/IF(OR(K17=TRUE,K17="TRUE",K17="YES",K17=1),1+'Settings'!$B$6/100,1),2) -> 49.1 | J17: 9.6 | K17: TRUE | L17: SUMMER15 | M17: =ROUND(E17*G17-H17,2) -> 59.41 | N17: =IF(COUNTIF($A$3:A17,A17)=1,1,0) -> 1 | O17: =IF(N17=1,ROUND((SUMIFS($M$3:$M$1200,$A$3:$A$1200,A17)+'Settings'!$B$13)*'Settings'!$B$14/100+'Settings'!$B$15,2),0) -> 2.07
A18: #1011 | B18: 2025-10-26 | C18: SKU-G | D18: Daily Reset Set | E18: =IF('Settings'!$B$11="Scenario",IFERROR(INDEX('Catalogue'!$E$3:$E$100,MATCH(C18,'Catalogue'!$B$3:$B$100,0)),F18),F18) -> 69 | F18: 69 | G18: 1 | H18: =IF('Settings'!$B$11="Scenario",ROUND(E18*G18*IFERROR(SUMIF('Pricing & promotions'!$A$6:$A$8,L18,'Pricing & promotions'!$B$6:$B$8)/100,0),2),J18) -> 10.35 | I18: =ROUND((E18*G18-H18)/IF(OR(K18=TRUE,K18="TRUE",K18="YES",K18=1),1+'Settings'!$B$6/100,1),2) -> 48.47 | J18: 10.35 | K18: TRUE | L18: SUMMER15 | M18: =ROUND(E18*G18-H18,2) -> 58.65 | N18: =IF(COUNTIF($A$3:A18,A18)=1,1,0) -> 0 | O18: =IF(N18=1,ROUND((SUMIFS($M$3:$M$1200,$A$3:$A$1200,A18)+'Settings'!$B$13)*'Settings'!$B$14/100+'Settings'!$B$15,2),0) -> 0
A19: #1012 | B19: 2025-10-27 | C19: SKU-E | D19: Complete Ritual | E19: =IF('Settings'!$B$11="Scenario",IFERROR(INDEX('Catalogue'!$E$3:$E$100,MATCH(C19,'Catalogue'!$B$3:$B$100,0)),F19),F19) -> 89 | F19: 89 | G19: 1 | H19: =IF('Settings'!$B$11="Scenario",ROUND(E19*G19*IFERROR(SUMIF('Pricing & promotions'!$A$6:$A$8,L19,'Pricing & promotions'!$B$6:$B$8)/100,0),2),J19) -> 0 | I19: =ROUND((E19*G19-H19)/IF(OR(K19=TRUE,K19="TRUE",K19="YES",K19=1),1+'Settings'!$B$6/100,1),2) -> 73.55 | J19: 0 | K19: TRUE | M19: =ROUND(E19*G19-H19,2) -> 89 | N19: =IF(COUNTIF($A$3:A19,A19)=1,1,0) -> 1 | O19: =IF(N19=1,ROUND((SUMIFS($M$3:$M$1200,$A$3:$A$1200,A19)+'Settings'!$B$13)*'Settings'!$B$14/100+'Settings'!$B$15,2),0) -> 2.68
A20: #1012 | B20: 2025-10-27 | C20: SKU-A | D20: Renewal Serum | E20: =IF('Settings'!$B$11="Scenario",IFERROR(INDEX('Catalogue'!$E$3:$E$100,MATCH(C20,'Catalogue'!$B$3:$B$100,0)),F20),F20) -> 69.9 | F20: 64 | G20: 1 | H20: =IF('Settings'!$B$11="Scenario",ROUND(E20*G20*IFERROR(SUMIF('Pricing & promotions'!$A$6:$A$8,L20,'Pricing & promotions'!$B$6:$B$8)/100,0),2),J20) -> 0 | I20: =ROUND((E20*G20-H20)/IF(OR(K20=TRUE,K20="TRUE",K20="YES",K20=1),1+'Settings'!$B$6/100,1),2) -> 57.77 | J20: 0 | K20: TRUE | M20: =ROUND(E20*G20-H20,2) -> 69.9 | N20: =IF(COUNTIF($A$3:A20,A20)=1,1,0) -> 0 | O20: =IF(N20=1,ROUND((SUMIFS($M$3:$M$1200,$A$3:$A$1200,A20)+'Settings'!$B$13)*'Settings'!$B$14/100+'Settings'!$B$15,2),0) -> 0
A21: #1013 | B21: 2025-10-27 | C21: SKU-A | D21: Renewal Serum | E21: =IF('Settings'!$B$11="Scenario",IFERROR(INDEX('Catalogue'!$E$3:$E$100,MATCH(C21,'Catalogue'!$B$3:$B$100,0)),F21),F21) -> 69.9 | F21: 64 | G21: 1 | H21: =IF('Settings'!$B$11="Scenario",ROUND(E21*G21*IFERROR(SUMIF('Pricing & promotions'!$A$6:$A$8,L21,'Pricing & promotions'!$B$6:$B$8)/100,0),2),J21) -> 6.99 | I21: =ROUND((E21*G21-H21)/IF(OR(K21=TRUE,K21="TRUE",K21="YES",K21=1),1+'Settings'!$B$6/100,1),2) -> 51.99 | J21: 6.4 | K21: TRUE | L21: WELCOME10 | M21: =ROUND(E21*G21-H21,2) -> 62.91 | N21: =IF(COUNTIF($A$3:A21,A21)=1,1,0) -> 1 | O21: =IF(N21=1,ROUND((SUMIFS($M$3:$M$1200,$A$3:$A$1200,A21)+'Settings'!$B$13)*'Settings'!$B$14/100+'Settings'!$B$15,2),0) -> 1.49
A22: #1013 | B22: 2025-10-27 | C22: SKU-B | D22: Barrier Balm | E22: =IF('Settings'!$B$11="Scenario",IFERROR(INDEX('Catalogue'!$E$3:$E$100,MATCH(C22,'Catalogue'!$B$3:$B$100,0)),F22),F22) -> 19 | F22: 18 | G22: 1 | H22: =IF('Settings'!$B$11="Scenario",ROUND(E22*G22*IFERROR(SUMIF('Pricing & promotions'!$A$6:$A$8,L22,'Pricing & promotions'!$B$6:$B$8)/100,0),2),J22) -> 1.9 | I22: =ROUND((E22*G22-H22)/IF(OR(K22=TRUE,K22="TRUE",K22="YES",K22=1),1+'Settings'!$B$6/100,1),2) -> 14.13 | J22: 1.8 | K22: TRUE | L22: WELCOME10 | M22: =ROUND(E22*G22-H22,2) -> 17.1 | N22: =IF(COUNTIF($A$3:A22,A22)=1,1,0) -> 0 | O22: =IF(N22=1,ROUND((SUMIFS($M$3:$M$1200,$A$3:$A$1200,A22)+'Settings'!$B$13)*'Settings'!$B$14/100+'Settings'!$B$15,2),0) -> 0
A23: #1014 | B23: 2025-10-27 | C23: SKU-F | D23: Cloud Cleanser | E23: =IF('Settings'!$B$11="Scenario",IFERROR(INDEX('Catalogue'!$E$3:$E$100,MATCH(C23,'Catalogue'!$B$3:$B$100,0)),F23),F23) -> 34 | F23: 34 | G23: 1 | H23: =IF('Settings'!$B$11="Scenario",ROUND(E23*G23*IFERROR(SUMIF('Pricing & promotions'!$A$6:$A$8,L23,'Pricing & promotions'!$B$6:$B$8)/100,0),2),J23) -> 3.4 | I23: =ROUND((E23*G23-H23)/IF(OR(K23=TRUE,K23="TRUE",K23="YES",K23=1),1+'Settings'!$B$6/100,1),2) -> 25.29 | J23: 3.4 | K23: TRUE | L23: WELCOME10 | M23: =ROUND(E23*G23-H23,2) -> 30.6 | N23: =IF(COUNTIF($A$3:A23,A23)=1,1,0) -> 1 | O23: =IF(N23=1,ROUND((SUMIFS($M$3:$M$1200,$A$3:$A$1200,A23)+'Settings'!$B$13)*'Settings'!$B$14/100+'Settings'!$B$15,2),0) -> 0.75
A24: #1015 | B24: 2025-10-27 | C24: SKU-A | D24: Renewal Serum | E24: =IF('Settings'!$B$11="Scenario",IFERROR(INDEX('Catalogue'!$E$3:$E$100,MATCH(C24,'Catalogue'!$B$3:$B$100,0)),F24),F24) -> 69.9 | F24: 64 | G24: 1 | H24: =IF('Settings'!$B$11="Scenario",ROUND(E24*G24*IFERROR(SUMIF('Pricing & promotions'!$A$6:$A$8,L24,'Pricing & promotions'!$B$6:$B$8)/100,0),2),J24) -> 6.99 | I24: =ROUND((E24*G24-H24)/IF(OR(K24=TRUE,K24="TRUE",K24="YES",K24=1),1+'Settings'!$B$6/100,1),2) -> 51.99 | J24: 6.4 | K24: TRUE | L24: WELCOME10 | M24: =ROUND(E24*G24-H24,2) -> 62.91 | N24: =IF(COUNTIF($A$3:A24,A24)=1,1,0) -> 1 | O24: =IF(N24=1,ROUND((SUMIFS($M$3:$M$1200,$A$3:$A$1200,A24)+'Settings'!$B$13)*'Settings'!$B$14/100+'Settings'!$B$15,2),0) -> 1.24
A25: #1016 | B25: 2025-10-27 | C25: SKU-E | D25: Complete Ritual | E25: =IF('Settings'!$B$11="Scenario",IFERROR(INDEX('Catalogue'!$E$3:$E$100,MATCH(C25,'Catalogue'!$B$3:$B$100,0)),F25),F25) -> 89 | F25: 89 | G25: 2 | H25: =IF('Settings'!$B$11="Scenario",ROUND(E25*G25*IFERROR(SUMIF('Pricing & promotions'!$A$6:$A$8,L25,'Pricing & promotions'!$B$6:$B$8)/100,0),2),J25) -> 17.8 | I25: =ROUND((E25*G25-H25)/IF(OR(K25=TRUE,K25="TRUE",K25="YES",K25=1),1+'Settings'!$B$6/100,1),2) -> 132.4 | J25: 17.8 | K25: TRUE | L25: WELCOME10 | M25: =ROUND(E25*G25-H25,2) -> 160.2 | N25: =IF(COUNTIF($A$3:A25,A25)=1,1,0) -> 1 | O25: =IF(N25=1,ROUND((SUMIFS($M$3:$M$1200,$A$3:$A$1200,A25)+'Settings'!$B$13)*'Settings'!$B$14/100+'Settings'!$B$15,2),0) -> 2.7
A26: #1017 | B26: 2025-10-28 | C26: SKU-A | D26: Renewal Serum | E26: =IF('Settings'!$B$11="Scenario",IFERROR(INDEX('Catalogue'!$E$3:$E$100,MATCH(C26,'Catalogue'!$B$3:$B$100,0)),F26),F26) -> 69.9 | F26: 64 | G26: 1 | H26: =IF('Settings'!$B$11="Scenario",ROUND(E26*G26*IFERROR(SUMIF('Pricing & promotions'!$A$6:$A$8,L26,'Pricing & promotions'!$B$6:$B$8)/100,0),2),J26) -> 0 | I26: =ROUND((E26*G26-H26)/IF(OR(K26=TRUE,K26="TRUE",K26="YES",K26=1),1+'Settings'!$B$6/100,1),2) -> 57.77 | J26: 0 | K26: TRUE | M26: =ROUND(E26*G26-H26,2) -> 69.9 | N26: =IF(COUNTIF($A$3:A26,A26)=1,1,0) -> 1 | O26: =IF(N26=1,ROUND((SUMIFS($M$3:$M$1200,$A$3:$A$1200,A26)+'Settings'!$B$13)*'Settings'!$B$14/100+'Settings'!$B$15,2),0) -> 1.78
A27: #1017 | B27: 2025-10-28 | C27: SKU-C | D27: Contour Stone | E27: =IF('Settings'!$B$11="Scenario",IFERROR(INDEX('Catalogue'!$E$3:$E$100,MATCH(C27,'Catalogue'!$B$3:$B$100,0)),F27),F27) -> 29 | F27: 29 | G27: 1 | H27: =IF('Settings'!$B$11="Scenario",ROUND(E27*G27*IFERROR(SUMIF('Pricing & promotions'!$A$6:$A$8,L27,'Pricing & promotions'!$B$6:$B$8)/100,0),2),J27) -> 0 | I27: =ROUND((E27*G27-H27)/IF(OR(K27=TRUE,K27="TRUE",K27="YES",K27=1),1+'Settings'!$B$6/100,1),2) -> 23.97 | J27: 0 | K27: TRUE | M27: =ROUND(E27*G27-H27,2) -> 29 | N27: =IF(COUNTIF($A$3:A27,A27)=1,1,0) -> 0 | O27: =IF(N27=1,ROUND((SUMIFS($M$3:$M$1200,$A$3:$A$1200,A27)+'Settings'!$B$13)*'Settings'!$B$14/100+'Settings'!$B$15,2),0) -> 0
A28: #1018 | B28: 2025-10-29 | C28: SKU-A | D28: Renewal Serum | E28: =IF('Settings'!$B$11="Scenario",IFERROR(INDEX('Catalogue'!$E$3:$E$100,MATCH(C28,'Catalogue'!$B$3:$B$100,0)),F28),F28) -> 69.9 | F28: 64 | G28: 1 | H28: =IF('Settings'!$B$11="Scenario",ROUND(E28*G28*IFERROR(SUMIF('Pricing & promotions'!$A$6:$A$8,L28,'Pricing & promotions'!$B$6:$B$8)/100,0),2),J28) -> 0 | I28: =ROUND((E28*G28-H28)/IF(OR(K28=TRUE,K28="TRUE",K28="YES",K28=1),1+'Settings'!$B$6/100,1),2) -> 57.77 | J28: 0 | K28: TRUE | M28: =ROUND(E28*G28-H28,2) -> 69.9 | N28: =IF(COUNTIF($A$3:A28,A28)=1,1,0) -> 1 | O28: =IF(N28=1,ROUND((SUMIFS($M$3:$M$1200,$A$3:$A$1200,A28)+'Settings'!$B$13)*'Settings'!$B$14/100+'Settings'!$B$15,2),0) -> 2.14
A29: #1018 | B29: 2025-10-29 | C29: SKU-F | D29: Cloud Cleanser | E29: =IF('Settings'!$B$11="Scenario",IFERROR(INDEX('Catalogue'!$E$3:$E$100,MATCH(C29,'Catalogue'!$B$3:$B$100,0)),F29),F29) -> 34 | F29: 34 | G29: 1 | H29: =IF('Settings'!$B$11="Scenario",ROUND(E29*G29*IFERROR(SUMIF('Pricing & promotions'!$A$6:$A$8,L29,'Pricing & promotions'!$B$6:$B$8)/100,0),2),J29) -> 0 | I29: =ROUND((E29*G29-H29)/IF(OR(K29=TRUE,K29="TRUE",K29="YES",K29=1),1+'Settings'!$B$6/100,1),2) -> 28.1 | J29: 0 | K29: TRUE | M29: =ROUND(E29*G29-H29,2) -> 34 | N29: =IF(COUNTIF($A$3:A29,A29)=1,1,0) -> 0 | O29: =IF(N29=1,ROUND((SUMIFS($M$3:$M$1200,$A$3:$A$1200,A29)+'Settings'!$B$13)*'Settings'!$B$14/100+'Settings'!$B$15,2),0) -> 0
A30: #1018 | B30: 2025-10-29 | C30: SKU-B | D30: Barrier Balm | E30: =IF('Settings'!$B$11="Scenario",IFERROR(INDEX('Catalogue'!$E$3:$E$100,MATCH(C30,'Catalogue'!$B$3:$B$100,0)),F30),F30) -> 19 | F30: 18 | G30: 1 | H30: =IF('Settings'!$B$11="Scenario",ROUND(E30*G30*IFERROR(SUMIF('Pricing & promotions'!$A$6:$A$8,L30,'Pricing & promotions'!$B$6:$B$8)/100,0),2),J30) -> 0 | I30: =ROUND((E30*G30-H30)/IF(OR(K30=TRUE,K30="TRUE",K30="YES",K30=1),1+'Settings'!$B$6/100,1),2) -> 15.7 | J30: 0 | K30: TRUE | M30: =ROUND(E30*G30-H30,2) -> 19 | N30: =IF(COUNTIF($A$3:A30,A30)=1,1,0) -> 0 | O30: =IF(N30=1,ROUND((SUMIFS($M$3:$M$1200,$A$3:$A$1200,A30)+'Settings'!$B$13)*'Settings'!$B$14/100+'Settings'!$B$15,2),0) -> 0
A31: #1019 | B31: 2025-10-29 | C31: SKU-G | D31: Daily Reset Set | E31: =IF('Settings'!$B$11="Scenario",IFERROR(INDEX('Catalogue'!$E$3:$E$100,MATCH(C31,'Catalogue'!$B$3:$B$100,0)),F31),F31) -> 69 | F31: 69 | G31: 1 | H31: =IF('Settings'!$B$11="Scenario",ROUND(E31*G31*IFERROR(SUMIF('Pricing & promotions'!$A$6:$A$8,L31,'Pricing & promotions'!$B$6:$B$8)/100,0),2),J31) -> 0 | I31: =ROUND((E31*G31-H31)/IF(OR(K31=TRUE,K31="TRUE",K31="YES",K31=1),1+'Settings'!$B$6/100,1),2) -> 57.02 | J31: 0 | K31: TRUE | M31: =ROUND(E31*G31-H31,2) -> 69 | N31: =IF(COUNTIF($A$3:A31,A31)=1,1,0) -> 1 | O31: =IF(N31=1,ROUND((SUMIFS($M$3:$M$1200,$A$3:$A$1200,A31)+'Settings'!$B$13)*'Settings'!$B$14/100+'Settings'!$B$15,2),0) -> 2.38
A32: #1019 | B32: 2025-10-29 | C32: SKU-A | D32: Renewal Serum | E32: =IF('Settings'!$B$11="Scenario",IFERROR(INDEX('Catalogue'!$E$3:$E$100,MATCH(C32,'Catalogue'!$B$3:$B$100,0)),F32),F32) -> 69.9 | F32: 64 | G32: 1 | H32: =IF('Settings'!$B$11="Scenario",ROUND(E32*G32*IFERROR(SUMIF('Pricing & promotions'!$A$6:$A$8,L32,'Pricing & promotions'!$B$6:$B$8)/100,0),2),J32) -> 0 | I32: =ROUND((E32*G32-H32)/IF(OR(K32=TRUE,K32="TRUE",K32="YES",K32=1),1+'Settings'!$B$6/100,1),2) -> 57.77 | J32: 0 | K32: TRUE | M32: =ROUND(E32*G32-H32,2) -> 69.9 | N32: =IF(COUNTIF($A$3:A32,A32)=1,1,0) -> 0 | O32: =IF(N32=1,ROUND((SUMIFS($M$3:$M$1200,$A$3:$A$1200,A32)+'Settings'!$B$13)*'Settings'!$B$14/100+'Settings'!$B$15,2),0) -> 0
A33: #1020 | B33: 2025-10-29 | C33: SKU-G | D33: Daily Reset Set | E33: =IF('Settings'!$B$11="Scenario",IFERROR(INDEX('Catalogue'!$E$3:$E$100,MATCH(C33,'Catalogue'!$B$3:$B$100,0)),F33),F33) -> 69 | F33: 69 | G33: 1 | H33: =IF('Settings'!$B$11="Scenario",ROUND(E33*G33*IFERROR(SUMIF('Pricing & promotions'!$A$6:$A$8,L33,'Pricing & promotions'!$B$6:$B$8)/100,0),2),J33) -> 6.9 | I33: =ROUND((E33*G33-H33)/IF(OR(K33=TRUE,K33="TRUE",K33="YES",K33=1),1+'Settings'!$B$6/100,1),2) -> 51.32 | J33: 6.9 | K33: TRUE | L33: WELCOME10 | M33: =ROUND(E33*G33-H33,2) -> 62.1 | N33: =IF(COUNTIF($A$3:A33,A33)=1,1,0) -> 1 | O33: =IF(N33=1,ROUND((SUMIFS($M$3:$M$1200,$A$3:$A$1200,A33)+'Settings'!$B$13)*'Settings'!$B$14/100+'Settings'!$B$15,2),0) -> 1.23
A34: #1021 | B34: 2025-10-30 | C34: SKU-C | D34: Contour Stone | E34: =IF('Settings'!$B$11="Scenario",IFERROR(INDEX('Catalogue'!$E$3:$E$100,MATCH(C34,'Catalogue'!$B$3:$B$100,0)),F34),F34) -> 29 | F34: 29 | G34: 1 | H34: =IF('Settings'!$B$11="Scenario",ROUND(E34*G34*IFERROR(SUMIF('Pricing & promotions'!$A$6:$A$8,L34,'Pricing & promotions'!$B$6:$B$8)/100,0),2),J34) -> 2.9 | I34: =ROUND((E34*G34-H34)/IF(OR(K34=TRUE,K34="TRUE",K34="YES",K34=1),1+'Settings'!$B$6/100,1),2) -> 21.57 | J34: 2.9 | K34: TRUE | L34: WELCOME10 | M34: =ROUND(E34*G34-H34,2) -> 26.1 | N34: =IF(COUNTIF($A$3:A34,A34)=1,1,0) -> 1 | O34: =IF(N34=1,ROUND((SUMIFS($M$3:$M$1200,$A$3:$A$1200,A34)+'Settings'!$B$13)*'Settings'!$B$14/100+'Settings'!$B$15,2),0) -> 0.69
A35: #1022 | B35: 2025-10-30 | C35: SKU-A | D35: Renewal Serum | E35: =IF('Settings'!$B$11="Scenario",IFERROR(INDEX('Catalogue'!$E$3:$E$100,MATCH(C35,'Catalogue'!$B$3:$B$100,0)),F35),F35) -> 69.9 | F35: 64 | G35: 1 | H35: =IF('Settings'!$B$11="Scenario",ROUND(E35*G35*IFERROR(SUMIF('Pricing & promotions'!$A$6:$A$8,L35,'Pricing & promotions'!$B$6:$B$8)/100,0),2),J35) -> 6.99 | I35: =ROUND((E35*G35-H35)/IF(OR(K35=TRUE,K35="TRUE",K35="YES",K35=1),1+'Settings'!$B$6/100,1),2) -> 51.99 | J35: 6.4 | K35: TRUE | L35: WELCOME10 | M35: =ROUND(E35*G35-H35,2) -> 62.91 | N35: =IF(COUNTIF($A$3:A35,A35)=1,1,0) -> 1 | O35: =IF(N35=1,ROUND((SUMIFS($M$3:$M$1200,$A$3:$A$1200,A35)+'Settings'!$B$13)*'Settings'!$B$14/100+'Settings'!$B$15,2),0) -> 1.24
A36: #1023 | B36: 2025-10-30 | C36: SKU-D | D36: Daily Duo | E36: =IF('Settings'!$B$11="Scenario",IFERROR(INDEX('Catalogue'!$E$3:$E$100,MATCH(C36,'Catalogue'!$B$3:$B$100,0)),F36),F36) -> 79 | F36: 79 | G36: 2 | H36: =IF('Settings'!$B$11="Scenario",ROUND(E36*G36*IFERROR(SUMIF('Pricing & promotions'!$A$6:$A$8,L36,'Pricing & promotions'!$B$6:$B$8)/100,0),2),J36) -> 0 | I36: =ROUND((E36*G36-H36)/IF(OR(K36=TRUE,K36="TRUE",K36="YES",K36=1),1+'Settings'!$B$6/100,1),2) -> 130.58 | J36: 0 | K36: TRUE | M36: =ROUND(E36*G36-H36,2) -> 158 | N36: =IF(COUNTIF($A$3:A36,A36)=1,1,0) -> 1 | O36: =IF(N36=1,ROUND((SUMIFS($M$3:$M$1200,$A$3:$A$1200,A36)+'Settings'!$B$13)*'Settings'!$B$14/100+'Settings'!$B$15,2),0) -> 2.66
A37: #1024 | B37: 2025-10-31 | C37: SKU-G | D37: Daily Reset Set | E37: =IF('Settings'!$B$11="Scenario",IFERROR(INDEX('Catalogue'!$E$3:$E$100,MATCH(C37,'Catalogue'!$B$3:$B$100,0)),F37),F37) -> 69 | F37: 69 | G37: 1 | H37: =IF('Settings'!$B$11="Scenario",ROUND(E37*G37*IFERROR(SUMIF('Pricing & promotions'!$A$6:$A$8,L37,'Pricing & promotions'!$B$6:$B$8)/100,0),2),J37) -> 0 | I37: =ROUND((E37*G37-H37)/IF(OR(K37=TRUE,K37="TRUE",K37="YES",K37=1),1+'Settings'!$B$6/100,1),2) -> 57.02 | J37: 0 | K37: TRUE | M37: =ROUND(E37*G37-H37,2) -> 69 | N37: =IF(COUNTIF($A$3:A37,A37)=1,1,0) -> 1 | O37: =IF(N37=1,ROUND((SUMIFS($M$3:$M$1200,$A$3:$A$1200,A37)+'Settings'!$B$13)*'Settings'!$B$14/100+'Settings'!$B$15,2),0) -> 1.33
A38: #1025 | B38: 2025-11-01 | C38: SKU-F | D38: Cloud Cleanser | E38: =IF('Settings'!$B$11="Scenario",IFERROR(INDEX('Catalogue'!$E$3:$E$100,MATCH(C38,'Catalogue'!$B$3:$B$100,0)),F38),F38) -> 34 | F38: 34 | G38: 1 | H38: =IF('Settings'!$B$11="Scenario",ROUND(E38*G38*IFERROR(SUMIF('Pricing & promotions'!$A$6:$A$8,L38,'Pricing & promotions'!$B$6:$B$8)/100,0),2),J38) -> 0 | I38: =ROUND((E38*G38-H38)/IF(OR(K38=TRUE,K38="TRUE",K38="YES",K38=1),1+'Settings'!$B$6/100,1),2) -> 28.1 | J38: 0 | K38: TRUE | M38: =ROUND(E38*G38-H38,2) -> 34 | N38: =IF(COUNTIF($A$3:A38,A38)=1,1,0) -> 1 | O38: =IF(N38=1,ROUND((SUMIFS($M$3:$M$1200,$A$3:$A$1200,A38)+'Settings'!$B$13)*'Settings'!$B$14/100+'Settings'!$B$15,2),0) -> 1.85
A39: #1025 | B39: 2025-11-01 | C39: SKU-A | D39: Renewal Serum | E39: =IF('Settings'!$B$11="Scenario",IFERROR(INDEX('Catalogue'!$E$3:$E$100,MATCH(C39,'Catalogue'!$B$3:$B$100,0)),F39),F39) -> 69.9 | F39: 64 | G39: 1 | H39: =IF('Settings'!$B$11="Scenario",ROUND(E39*G39*IFERROR(SUMIF('Pricing & promotions'!$A$6:$A$8,L39,'Pricing & promotions'!$B$6:$B$8)/100,0),2),J39) -> 0 | I39: =ROUND((E39*G39-H39)/IF(OR(K39=TRUE,K39="TRUE",K39="YES",K39=1),1+'Settings'!$B$6/100,1),2) -> 57.77 | J39: 0 | K39: TRUE | M39: =ROUND(E39*G39-H39,2) -> 69.9 | N39: =IF(COUNTIF($A$3:A39,A39)=1,1,0) -> 0 | O39: =IF(N39=1,ROUND((SUMIFS($M$3:$M$1200,$A$3:$A$1200,A39)+'Settings'!$B$13)*'Settings'!$B$14/100+'Settings'!$B$15,2),0) -> 0
A40: #1026 | B40: 2025-11-01 | C40: SKU-F | D40: Cloud Cleanser | E40: =IF('Settings'!$B$11="Scenario",IFERROR(INDEX('Catalogue'!$E$3:$E$100,MATCH(C40,'Catalogue'!$B$3:$B$100,0)),F40),F40) -> 34 | F40: 34 | G40: 1 | H40: =IF('Settings'!$B$11="Scenario",ROUND(E40*G40*IFERROR(SUMIF('Pricing & promotions'!$A$6:$A$8,L40,'Pricing & promotions'!$B$6:$B$8)/100,0),2),J40) -> 3.4 | I40: =ROUND((E40*G40-H40)/IF(OR(K40=TRUE,K40="TRUE",K40="YES",K40=1),1+'Settings'!$B$6/100,1),2) -> 25.29 | J40: 3.4 | K40: TRUE | L40: WELCOME10 | M40: =ROUND(E40*G40-H40,2) -> 30.6 | N40: =IF(COUNTIF($A$3:A40,A40)=1,1,0) -> 1 | O40: =IF(N40=1,ROUND((SUMIFS($M$3:$M$1200,$A$3:$A$1200,A40)+'Settings'!$B$13)*'Settings'!$B$14/100+'Settings'!$B$15,2),0) -> 0.75
...
